Workbook

Sheet Lista de Precios 10-02
A1: Código | B1: Cód.Barras U.Consumo | C1: Descripcion | D1: Tradicional (c/Iva) | E1: Marca
A2: 122404 | C2: =VLOOKUP(A2,BASE!A:C,2,FALSE) -> ESFREBOM ESPONJA AUTOMOTOR x36 un | D2: =VLOOKUP(A2,BASE!A:C,3,FALSE) -> 2669.99 | E2: 7
A3: 122448 | C3: =VLOOKUP(A3,BASE!A:C,2,FALSE) -> ESFREBOM ESPONJA DIAMANTADA x60 un | D3: =VLOOKUP(A3,BASE!A:C,3,FALSE) -> 728.18 | E3: 7
A4: 122495 | C4: =VLOOKUP(A4,BASE!A:C,2,FALSE) -> ESFREBOM ESPONJA DOBLE CARA x60 un | D4: =VLOOKUP(A4,BASE!A:C,3,FALSE) -> 1372.54 | E4: 7
A5: 122484 | C5: =VLOOKUP(A5,BASE!A:C,2,FALSE) -> ESFREBOM ESPONJA METALIZADA x60 un | D5: =VLOOKUP(A5,BASE!A:C,3,FALSE) -> 1071.68 | E5: 7
A6: 122453 | C6: =VLOOKUP(A6,BASE!A:C,2,FALSE) -> ESFREBOM ESPONJA PARRILLERA x60 un | D6: =VLOOKUP(A6,BASE!A:C,3,FALSE) -> 1031.59 | E6: 7
A7: 122452 | C7: =VLOOKUP(A7,BASE!A:C,2,FALSE) -> ESFREBOM ESPONJA SALVA UÑAS (X60) x1 un | D7: =VLOOKUP(A7,BASE!A:C,3,FALSE) -> 789.73 | E7: 7
A8: 122456 | C8: =VLOOKUP(A8,BASE!A:C,2,FALSE) -> ESFREBOM ESPONJA TEFLON x60 un | D8: =VLOOKUP(A8,BASE!A:C,3,FALSE) -> 485.45 | E8: 7
A9: 1221323 | C9: =VLOOKUP(A9,BASE!A:C,2,FALSE) -> ESFREBOM GUANTES DE COCINA "P" x12 un | D9: =VLOOKUP(A9,BASE!A:C,3,FALSE) -> 2061.78 | E9: 7
A10: 1221322 | C10: =VLOOKUP(A10,BASE!A:C,2,FALSE) -> ESFREBOM GUANTES DE COCINA "M" x12 un | D10: =VLOOKUP(A10,BASE!A:C,3,FALSE) -> 2061.78 | E10: 7
A11: 1221321 | C11: =VLOOKUP(A11,BASE!A:C,2,FALSE) -> ESFREBOM GUANTES DE COCINA "G" x12 un | D11: =VLOOKUP(A11,BASE!A:C,3,FALSE) -> 2061.78 | E11: 7
A12: 122201 | C12: =VLOOKUP(A12,BASE!A:C,2,FALSE) -> ESFREBOM ROLLO SACA PELUSA x24 un | D12: =VLOOKUP(A12,BASE!A:C,3,FALSE) -> 2275.82 | E12: 7
A13: 1222064 | C13: =VLOOKUP(A13,BASE!A:C,2,FALSE) -> BRILHUS BROCHES DE ROPA x12 un | D13: =VLOOKUP(A13,BASE!A:C,3,FALSE) -> 1887.7 | E13: 7
... A17: 122570 | C17: =VLOOKUP(A17,BASE!A:C,2,FALSE) -> BETTANIN CEPILLO SANITARIO x36 un | D17: =VLOOKUP(A17,BASE!A:C,3,FALSE) -> 3515.76 | E17: 7
A18: 109351 | B18: 7790770603015 | C18: =VLOOKUP(A18,BASE!A:C,2,FALSE) -> CALIPSO PD NORMAL ROSA X 30U x32 un | D18: =VLOOKUP(A18,BASE!A:C,3,FALSE) -> 1263.88 | E18: 1
A19: 105597 | B19: 7790770602186 | C19: =VLOOKUP(A19,BASE!A:C,2,FALSE) -> CALIPSO PD NORMAL ROSA X 20U x40 un | D19: =VLOOKUP(A19,BASE!A:C,3,FALSE) -> 1011.11 | E19: 1
A20: 105552 | B20: 7790770602193 | C20: =VLOOKUP(A20,BASE!A:C,2,FALSE) -> CALIPSO PD NORMAL ROSA X 50U x20 un | D20: =VLOOKUP(A20,BASE!A:C,3,FALSE) -> 2055.51 | E20: 1
A21: 105599 | B21: 7790770602209 | C21: =VLOOKUP(A21,BASE!A:C,2,FALSE) -> CALIPSO PD NORMAL ROSA X 80U x10 un | D21: =VLOOKUP(A21,BASE!A:C,3,FALSE) -> 3002.19 | E21: 1
A22: 105596 | B22: 7790770602285 | C22: =VLOOKUP(A22,BASE!A:C,2,FALSE) -> CALIPSO PD NORMAL C/FRAG X 20U x40 un | D22: =VLOOKUP(A22,BASE!A:C,3,FALSE) -> 1011.11 | E22: 1
A23: 105550 | B23: 7790770602254 | C23: =VLOOKUP(A23,BASE!A:C,2,FALSE) -> CALIPSO PD NORMAL C/FRAG X 50U x20 un | D23: =VLOOKUP(A23,BASE!A:C,3,FALSE) -> 2055.51 | E23: 1
A24: 105988 | B24: 7790770602261 | C24: =VLOOKUP(A24,BASE!A:C,2,FALSE) -> CALIPSO PD TANGA ROSA X 20U x40 un | D24: =VLOOKUP(A24,BASE!A:C,3,FALSE) -> 1216.63 | E24: 1
A25: 105553 | B25: 7790770602278 | C25: =VLOOKUP(A25,BASE!A:C,2,FALSE) -> CALIPSO PD TANGA ROSA X 50U x10 un | D25: =VLOOKUP(A25,BASE!A:C,3,FALSE) -> 2627.58 | E25: 1
A26: 105093 | B26: 7790770602216 | C26: =VLOOKUP(A26,BASE!A:C,2,FALSE) -> CALIPSO PD MULTIESTILO NARANJA X 20U x40 un | D26: =VLOOKUP(A26,BASE!A:C,3,FALSE) -> 1216.63 | E26: 1
A27: 105558 | B27: 7790770602223 | C27: =VLOOKUP(A27,BASE!A:C,2,FALSE) -> CALIPSO PD MULTIESTILO NARANJA X 50U x10 un | D27: =VLOOKUP(A27,BASE!A:C,3,FALSE) -> 2627.58 | E27: 1
A28: 105420 | B28: 7790770602230 | C28: =VLOOKUP(A28,BASE!A:C,2,FALSE) -> CALIPSO PD RESPIRABLE CELESTE X 20U x40 un | D28: =VLOOKUP(A28,BASE!A:C,3,FALSE) -> 1011.11 | E28: 1
A29: 105421 | B29: 7790770602247 | C29: =VLOOKUP(A29,BASE!A:C,2,FALSE) -> CALIPSO PD RESPIRABLE CELESTE X 50U x10 un | D29: =VLOOKUP(A29,BASE!A:C,3,FALSE) -> 2055.51 | E29: 1
... A51: 106112 | B51: 7790770602018 | C51: =VLOOKUP(A51,BASE!A:C,2,FALSE) -> NOSOTRAS PD RESPIRABLE X 50U x12 un | D51: =VLOOKUP(A51,BASE!A:C,3,FALSE) -> 5571.92 | E51: 2
A52: 42424 | C52: =VLOOKUP(A52,BASE!A:C,2,FALSE) -> NOSOTRAS TAMPONES DIGITAL MINI X 8U x12 un | D52: =VLOOKUP(A52,BASE!A:C,3,FALSE) -> 3346.93 | E52: 2
A53: 203926 | B53: 7702026194581 | C53: =VLOOKUP(A53,BASE!A:C,2,FALSE) -> NOSOTRAS TAMPONES DIGITAL REGULAR X 8U x12 un | D53: =VLOOKUP(A53,BASE!A:C,3,FALSE) -> 3346.93 | E53: 2
A54: 204201 | B54: 7702026194710 | C54: =VLOOKUP(A54,BASE!A:C,2,FALSE) -> NOSOTRAS TAMPONES DIGITAL REGULAR X 16U x12 un | D54: =VLOOKUP(A54,BASE!A:C,3,FALSE) -> 6023.4 | E54: 2
A55: 203927 | B55: 7702026194697 | C55: =VLOOKUP(A55,BASE!A:C,2,FALSE) -> NOSOTRAS TAMPONES DIGITAL SUPER X 8U x12 un | D55: =VLOOKUP(A55,BASE!A:C,3,FALSE) -> 3346.93 | E55: 2
A56: 42426 | B56: 7702026194727 | C56: =VLOOKUP(A56,BASE!A:C,2,FALSE) -> NOSOTRAS TAMPONES DIGITAL SUPER X 16U x12 un | D56: =VLOOKUP(A56,BASE!A:C,3,FALSE) -> 6023.4 | E56: 2
A57: 110127 | B57: 7790770601882 | C57: =VLOOKUP(A57,BASE!A:C,2,FALSE) -> NOSOTRAS TOALLA CLASICA TELA X8U x30 un | D57: =VLOOKUP(A57,BASE!A:C,3,FALSE) -> 1813.81 | E57: 2
A58: 110129 | B58: 7790770601899 | C58: =VLOOKUP(A58,BASE!A:C,2,FALSE) -> NOSOTRAS TOALLA CLASICA TELA X 16U x15 un | D58: =VLOOKUP(A58,BASE!A:C,3,FALSE) -> 3429.54 | E58: 2
A59: 110230 | B59: 7790770602339 | C59: =VLOOKUP(A59,BASE!A:C,2,FALSE) -> NOSOTRAS TOALLA CLASICA TELA X 30U x8 un | D59: =VLOOKUP(A59,BASE!A:C,3,FALSE) -> 6104.53 | E59: 2
A60: 110185 | B60: 7790770601905 | C60: =VLOOKUP(A60,BASE!A:C,2,FALSE) -> NOSOTRAS TOALLA NORMAL TELA ALGODON X8U x30 un | D60: =VLOOKUP(A60,BASE!A:C,3,FALSE) -> 2198.19 | E60: 2
A61: 110186 | B61: 7790770601912 | C61: =VLOOKUP(A61,BASE!A:C,2,FALSE) -> NOSOTRAS TOALLA NORMAL X 16U x15 un | D61: =VLOOKUP(A61,BASE!A:C,3,FALSE) -> 3904.65 | E61: 2
A62: 120347 | B62: 7702026195830 | C62: =VLOOKUP(A62,BASE!A:C,2,FALSE) -> NOSOTRAS TOALLA CLASICA RAPISEC X 8U x30 un | D62: =VLOOKUP(A62,BASE!A:C,3,FALSE) -> 1815.42 | E62: 2
A63: 120348 | B63: 7702026195847 | C63: =VLOOKUP(A63,BASE!A:C,2,FALSE) -> NOSOTRAS TOALLA CLASICA RAPISEC X 16U x15 un | D63: =VLOOKUP(A63,BASE!A:C,3,FALSE) -> 3433.33 | E63: 2
A64: 110187 | B64: 7790770601950 | C64: =VLOOKUP(A64,BASE!A:C,2,FALSE) -> NOSOTRAS TOALLA CLASICAS ESENCIAL X8U x30 un | D64: =VLOOKUP(A64,BASE!A:C,3,FALSE) -> 1407.15 | E64: 2
...

Sheet BASE
A1: Código | B1: Descripcion | C1: TRADICIONAL (c/Iva)
A2: 122570 | B2: BETTANIN CEPILLO SANITARIO x36 un | C2: 3515.76
A3: 1222064 | B3: BRILHUS BROCHES DE ROPA x12 un | C3: 1887.7
A4: 1258 | B4: NATURAL HONEY BÁLSAMO LABIAL SABOR FRUTI x24 un
A5: 10202 | B5: ORAL-B PASTA DENTAL 3D WHITE BRILLANTE F x12 un | C5: 5671.88
A6: 10201 | B6: ORAL-B PASTA DENTAL 3D WHITE CON CARBON x12 un | C6: 5671.88
A7: 10200 | B7: ORAL-B PASTA DENTAL KIDS SPIDERMAN 100G x12 un | C7: 3781.25
A8: 1800 | B8: SOY TU FAN STICK MAQ. ARTÍSTICO BANDERA x144 un
A9: 10091324 | B9: TYL DELINEADOR DE CEJAS x1 un | C9: 1815
A10: 3367234 | B10: ALGABO BABY ACEITE P/ BEBE 200 ML x12 un | C10: 4249.05
A11: 38881 | B11: VN ACEITE SOLAR FPS 10 X 190ML x12 un | C11: 10000
A12: 841010 | B12: ESCUDO MATA CUCARACHAS Y HORMIGAS S/OLOR x12 un | C12: 3991.73
A13: 103026 | B13: SAPHIRUS AEROSOL BUBBLEGUM 185 G x12 un | C13: 5450.87
A14: 103001 | B14: SAPHIRUS AEROSOL AMOR 185 G x12 un | C14: 5450.87
A15: 103013 | B15: SAPHIRUS AEROSOL APOLO 185G x12 un | C15: 5450.87
A16: 103012 | B16: SAPHIRUS AEROSOL ATLANTIS 185G x12 un | C16: 5450.87
A17: 103022 | B17: SAPHIRUS AEROSOL BAMBOO 185 G x12 un | C17: 5450.87
A18: 103048 | B18: SAPHIRUS AEROSOL BEBE 185 G x12 un | C18: 5450.87
A19: 103009 | B19: SAPHIRUS AEROSOL BLOSSOM ROUGE 185 G x12 un | C19: 5450.87
A20: 103014 | B20: SAPHIRUS AEROSOL BLUE 185 G x12 un | C20: 5450.87
... A80: 6010251 | B80: ALGABO VAIS SPRAY 250ML CALIDA PRIMAVERA x16 un | C80: 3012.45
A81: 1010684 | B81: ALGABO VAIS SPRAY 250ML DULCES MIMOS x16 un
A82: 6010253 | B82: ALGABO VAIS SPRAY 250ML SUAVE BRISA TEXT x16 un | C82: 3012.45
A83: 10019164 | B83: DAMAR ARQUEADOR PESTAÑA ARO GOMA x1 un | C83: 775.59
A84: 43582 | B84: VN AUTOBRONCEANTE POMO X 150ML x12 un | C84: 10000
A85: 582292 | B85: I LOVE BICARBONATO D/P X 100G x24 un | C85: 1300.42
A86: 582308 | B86: I LOVE BICARBONATO X500G x12 un | C86: 5198.65
A87: 4032130 | B87: ALGABO FROZEN BODY SPLASH ELSA C/EST 125 x12 un | C87: 6082.84
A88: 3832122 | B88: ALGABO HELLO KITTY BODY.S ALEGRÍA X125 x12 un | C88: 6082.84
A89: 3032001 | B89: ALGABO KIDS PAW PATROL BODY SPLASH X125M x12 un | C89: 5832.86
A90: 3000001 | B90: ALGABO KIDS PAW PATROL SET BODY.S Y SH x12 un | C90: 9221.48
A91: 3832121 | B91: ALGABO KUROMI BODY.S DULZURA X120ML x12 un | C91: 6082.84
A92: 92639 | B92: CARO CUORE BODY MIST AMORE X120ML x6 un | C92: 15294.12
A93: 61556 | B93: CARO CUORE BODY MIST COURE X120ML x6 un | C93: 15294.12
A94: 65951 | B94: CARO CUORE BODY MIST X120ML x6 un | C94: 15294.12
A95: 536 | B95: CHIMOLA BODY MIST BRAVE 100ML x12 un
A96: 534 | B96: CHIMOLA BODY MIST CHIC 100ML x12 un
A97: 533 | B97: CHIMOLA BODY MIST ICONIC 100ML x12 un
A98: 535 | B98: CHIMOLA BODY MIST WILD 100ML x12 un
A99: 3232002 | B99: GO TO BE BODY SPLASH CHILL -ROSA X250ML x12 un | C99: 12586.8
...
